<?xml version="1.0"?>
<robot xmlns:xacro="http://www.ros.org/wiki/xacro" name="motors">

  <link name="base_link" />

  <link name="left_wheel" />
  <joint name="left_wheel_joint" type="continuous">
    <parent link="base_link" />
    <child link="left_wheel" />
  </joint>

  <link name="right_wheel" />
  <joint name="right_wheel_joint" type="continuous">
    <parent link="base_link" />
    <child link="right_wheel" />
  </joint>

  <!-- Connect your C++ Hardware Plugin -->
  <ros2_control name="PiMotorHardware" type="system">
    <hardware>
      <plugin>control_package/PiSystemHardware</plugin>
    </hardware>

    <joint name="left_wheel_joint">
      <command_interface name="velocity">
        <param name="min">-100</param>
        <param name="max">100</param>
      </command_interface>
      <state_interface name="position"/>
      <state_interface name="velocity"/>
    </joint>

    <joint name="right_wheel_joint">
      <command_interface name="velocity">
        <param name="min">-100</param>
        <param name="max">100</param>
      </command_interface>
      <state_interface name="position"/>
      <state_interface name="velocity"/>
    </joint>
  </ros2_control>

</robot>
